Workbook

Sheet Livros por Ano
A1: Catálogo Bibliográfico JUERP / Obras Batistas
A2: Lista de obras organizadas em ordem cronológica de publicação por ano e década
A4: Item | B4: Ano | C4: Década | D4: Título da Obra | E4: Autor(es) | F4: Editora / Selo | G4: Registro Original
A5: 1 | B5: 1906 | C5: Década de 1900 | D5: História dos Batistas do Brasil – VOLUME 1 | E5: até 1906 | F5: Casa Publicadora Batista | G5: História dos Batistas do Brasil – VOLUME 1 - até 1906 – A.R. CRABTREE – CASA PUBLICADORA BATISTA – 1962
A6: 2 | B6: 1907 | C6: Década de 1900 | D6: História dos Batistas do Brasil – VOLUME 2 | E6: de 1907 a 1935 | F6: Casa Publicadora Batista | G6: História dos Batistas do Brasil – VOLUME 2 - de 1907 a 1935 – ANTONIO NEVES DE MESQUITA – CASA PUBLICADORA BATISTA – 1962
A7: 3 | B7: 1915 | C7: Década de 1910 | D7: Palestras Para os Môços | E7: Confidenciaes | F7: ACM | G7: Palestras Para os Môços – Confidenciaes – ACM – 1915
A8: 4 | B8: 1921 | C8: Década de 1920 | E8: A INTERPRETAÇÃO DOS ACTOS DOS APÓSTOLOS SHEPARD, J.W. | F8: Casa Publicadora Baptista | G8: A INTERPRETAÇÃO DOS ACTOS DOS APÓSTOLOS SHEPARD, J.W. CASA PUBLICADORA BAPTISTA DO BRASIL 1921
A9: 5 | B9: 1921 | C9: Década de 1920 | D9: Interpretação dos Actos dos Apóstolos | E9: J.W. SHEPARD | F9: Casa Publicadora Baptista | G9: Interpretação dos Actos dos Apóstolos – J.W. SHEPARD – CASA PUBLICADORA BAPTISTA DO BRASIL – 1921
A10: 6 | B10: 1921 | C10: Década de 1920 | D10: Os Baptistas no Passado e no Futuro | E10: W.E. ENTZINGER -CASA PUBLICAORA BAPTISTA | F10: JUERP | G10: Os Baptistas no Passado e no Futuro – W.E. ENTZINGER -CASA PUBLICAORA BAPTISTA – 1921
A11: 7 | B11: 1922 | C11: Década de 1920 | D11: Os Baptistas e a Liberdade Religiosa | E11: 2a. Edição | F11: Casa Publicadora Baptista | G11: Os Baptistas e a Liberdade Religiosa – 2a. Edição – JORGE W. TRUETT – CASA PUBLICADORA BAPTISTA DO BRASIL 1922
A12: 8 | B12: 1922 | C12: Década de 1920 | D12: Os Baptistas e a Liberdade Religiosa | E12: JORGE W. TRUETT | F12: Casa Publicadora Baptista | G12: Os Baptistas e a Liberdade Religiosa – JORGE W. TRUETT – CASA PUBLICADORA BAPTISTA DO BRASIL – 1922
A13: 9 | B13: 1925 | C13: Década de 1920 | D13: O Sabbatismo à Luz da Palavra de Deus | E13: RICARDO PITROWSKY | F13: Casa Publicadora Baptista | G13: O Sabbatismo à Luz da Palavra de Deus – RICARDO PITROWSKY – CASA PUBLICADORA BAPTISTA – 1925
A14: 10 | B14: 1926 | C14: Década de 1920 | E14: TREINAMENTO NA MORDOMIA LEAVELL, F.H. | F14: Casa Publicadora Baptista | G14: TREINAMENTO NA MORDOMIA LEAVELL, F.H. CASA PUBLICADORA BAPTISTA 1926
A15: 11 | B15: 1926 | C15: Década de 1920 | D15: Lendas Hebraicas | E15: Tradições e Traducções | F15: Casa Publicadora Baptista | G15: Lendas Hebraicas – Tradições e Traducções – NICOLAU A. RODRIGUES – CASA PUBLICADORA BAPTISTA – 1926
A16: 12 | B16: 1926 | C16: Década de 1920 | D16: Treinamento na Mordomia | E16: F.H. HEAVELL | F16: Casa Publicadora Baptista | G16: Treinamento na Mordomia – F.H. HEAVELL – CASA PUBLICADORA BAPTISTA – 1926
A17: 13 | B17: 1927 | C17: Década de 1920 | D17: Notas Sobre Ethica Prática | E17: A.B. LANGSTON | F17: Casa Publicadora Baptista | G17: Notas Sobre Ethica Prática – A.B. LANGSTON – CASA PUBLICADORA BAPTISTA DO BRASIL – 1927
A18: 14 | B18: 1928 | C18: Década de 1920 | D18: Treinamento da Mordomia | E18: F. H. LEAVELLL | F18: Casa Publicadora Baptista | G18: Treinamento da Mordomia – F. H. LEAVELLL – CASA PUBLICADORA BAPTISTA – 1928
A19: 15 | B19: 1930 | C19: Década de 1930 | D19: Baptismo Biblico | E19: WILLIAM CAREY TAYLOR | F19: TYPOGRAFIA DO C.A.B. | G19: Baptismo Biblico – WILLIAM CAREY TAYLOR – TYPOGRAFIA DO C.A.B. – 1930
A20: 16 | B20: 1931 | C20: Década de 1930 | D20: O Escudo Diamantino | E20: SAMUEL JUDSON PORTER | F20: Casa Publicadora Baptista | G20: O Escudo Diamantino – SAMUEL JUDSON PORTER – CASA PUBLICADORA BAPTISTA – 1931
A21: 17 | B21: 1933 | C21: Década de 1930 | D21: Introdução ao Estudo do Novo Testamento Grego – TOMO II PARTE III | E21: W.C. TAYLOR | F21: TYPOGRAPHIA DO C.A.B. | G21: Introdução ao Estudo do Novo Testamento Grego – TOMO II PARTE III – W.C. TAYLOR – TYPOGRAPHIA DO C.A.B. 1933
A22: 18 | B22: 1934 | C22: Década de 1930 | D22: O Sabbatismo | E22: Um Systema Falso | F22: Casa Publicadora Baptista | G22: O Sabbatismo – Um Systema Falso – WILLIAM SICKLES – CASA PUBLICADORA BAPTISTA 1934
A23: 19 | B23: 1936 | C23: Década de 1930 | D23: Crenças Baptistas | E23: EDGAR YOUNG MULLINS | F23: Casa Publicadora Baptista | G23: Crenças Baptistas – EDGAR YOUNG MULLINS – CASA PUBLICADORA BAPTISTA – 1936
A24: 20 | B24: 1936 | C24: Década de 1930 | D24: Sermões do Púlpito Baptista | E24: MANOEL AVELINO DE SOUZA | F24: Casa Publicadora Baptista | G24: Sermões do Púlpito Baptista – MANOEL AVELINO DE SOUZA – CASA PUBLICADORA BAPTISTA – 1936
A25: 21 | B25: 1937 | C25: Década de 1930 | D25: A Doutrina do Espírito Santo | E25: A.B. LANGSTON | F25: Casa Publicadora Baptista | G25: A Doutrina do Espírito Santo – A.B. LANGSTON – CASA PUBLICADORA BAPTISTA 1937
A26: 22 | B26: 1937 | C26: Década de 1930 | D26: O Sabbatismo à Luz da Palavra de Deus | E26: RICARDO PITROWSKY | F26: Casa Publicadora Baptista | G26: O Sabbatismo à Luz da Palavra de Deus – RICARDO PITROWSKY – CASA PUBLICADORA BAPTISTA – 1937
A27: 23 | B27: 1938 | C27: Década de 1930 | E27: THEOLOGIA BIBLICA DO VELHO TESTAMENTO LANGSTON, A.B. | F27: Casa Publicadora Baptista | G27: THEOLOGIA BIBLICA DO VELHO TESTAMENTO LANGSTON, A.B. CASA PUBLICADORA BAPTISTA 1938
A28: 24 | B28: 1938 | C28: Década de 1930 | D28: Como Ganhar Almas Para Cristo | E28: WILLIAM EVANS | F28: Casa Publicadora Baptista | G28: Como Ganhar Almas Para Cristo – WILLIAM EVANS – CASA PUBLICADORA BAPTISTA – 1938
A29: 25 | B29: 1938 | C29: Década de 1930 | D29: Missões no Seu Compêndio | E29: A Bíblia | F29: Casa Publicadora Baptista | G29: Missões no Seu Compêndio – A Bíblia – L.M. BRATCHER – CASA PUBLICADORA BAPTISTA – 1938
A30: 26 | B30: 1940 | C30: Década de 1940 | D30: O Cristianismo Através dos Séculos – Volume 2 | E30: H.H. MUIRHEAD | F30: Casa Publicadora Batista | G30: O Cristianismo Através dos Séculos – Volume 2 – H.H. MUIRHEAD – CASA PUBLICADORA BATISTA 1940
A31: 27 | B31: 1940 | C31: Década de 1940 | D31: O Peregrino | E31: Adaptado para o Uso da Mocidade- L.P.LEAVELL | F31: Casa Publicadora Batista | G31: O Peregrino – Adaptado para o Uso da Mocidade- L.P.LEAVELL – CASA PUBLICADORA BATISTA- 1940
A32: 28 | B32: 1941 | C32: Década de 1940 | D32: Manual das Igrejas | E32: WILLIAM CAREY TAYLOR | F32: Casa Publicadora Batista | G32: Manual das Igrejas - WILLIAM CAREY TAYLOR – CASA PUBLICADORA BATISTA – 1941
A33: 29 | B33: 1941 | C33: Década de 1940 | D33: Os Escândalos | E33: ÁLVARO REIS | F33: Casa Publicadora Batista | G33: Os Escândalos – ÁLVARO REIS – CASA PUBLICADORA BATISTA – 1941
A34: 30 | B34: 1941 | C34: Década de 1940 | D34: Theologia Bíblica do Novo Testamento | E34: A.B. LANGSTON | F34: JUERP | G34: Theologia Bíblica do Novo Testamento – A.B. LANGSTON – 1941
A35: 31 | B35: 1942 | C35: Década de 1940 | D35: A Epístola de Tiago – Tradução e Comentário | E35: WILLIAM CAREY TAYLOR | F35: Casa Publicadora Batista | G35: A Epístola de Tiago – Tradução e Comentário – WILLIAM CAREY TAYLOR – CASA PUBLICADORA BATISTA – 1942
A36: 32 | B36: 1942 | C36: Década de 1940 | D36: A Sós Com Deus | E36: II Volume | F36: Casa Publicadora Batista | G36: A Sós Com Deus – II Volume – CASA PUBLICADORA BATISTA 1942
A37: 33 | B37: 1942 | C37: Década de 1940 | D37: Harmonia dos Evangelhos | E37: S.L. WATSON e W.E. ALLEN | F37: Casa Publicadora Batista | G37: Harmonia dos Evangelhos – S.L. WATSON e W.E. ALLEN – CASA PUBLICADORA BATISTA – 1942
A38: 34 | B38: 1942 | C38: Década de 1940 | D38: Passagens Bíblicas Explanadas | E38: W.C. TAYLOR | F38: Casa Publicadora Batista | G38: Passagens Bíblicas Explanadas – W.C. TAYLOR – CASA PUBLICADORA BATISTA – 1942
A39: 35 | B39: 1943 | C39: Década de 1940 | D39: De Adão a Malaquias | E39: P.E. BURROUGHS | F39: Casa Publicadora Batista | G39: De Adão a Malaquias – P.E. BURROUGHS – CASA PUBLICADORA BATISTA – 1943
... A48: 44 | B48: 1946 | C48: Década de 1940 | D48: O Espírito Santo | E48: ENÉAS TOGNINI | F48: Casa Publicadora Batista | G48: O Espírito Santo – ENÉAS TOGNINI – CASA PUBLICADORA BATISTA – 1946
A49: 45 | B49: 1947 | C49: Década de 1940 | E49: SOB OS CÉUS DA PALESTINA FRANÇA, MÁRIO BARRETO | F49: Casa Publicadora Batista | G49: SOB OS CÉUS DA PALESTINA FRANÇA, MÁRIO BARRETO CASA PUBLICADORA BATISTA 1947
...

Sheet Resumo por Década
A1: Distribuição Temporal das Obras Publicadas
A2: Contagem e proporção das obras catalogadas agrupadas por períodos/décadas
A4: Período / Década | B4: Quantidade de Obras | C4: Percentual (%)
A5: Década de 1910 | B5: =COUNTIF('Livros por Ano'!$C$5:$C$439, A5) -> 1 | C5: =B5/$B$18 -> #DIV/0!
A6: Década de 1920 | B6: =COUNTIF('Livros por Ano'!$C$5:$C$439, A6) -> 11 | C6: =B6/$B$18 -> #DIV/0!
A7: Década de 1930 | B7: =COUNTIF('Livros por Ano'!$C$5:$C$439, A7) -> 11 | C7: =B7/$B$18 -> #DIV/0!
A8: Década de 1940 | B8: =COUNTIF('Livros por Ano'!$C$5:$C$439, A8) -> 35 | C8: =B8/$B$18 -> #DIV/0!
A9: Década de 1950 | B9: =COUNTIF('Livros por Ano'!$C$5:$C$439, A9) -> 70 | C9: =B9/$B$18 -> #DIV/0!
A10: Década de 1960 | B10: =COUNTIF('Livros por Ano'!$C$5:$C$439, A10) -> 55 | C10: =B10/$B$18 -> #DIV/0!
A11: Década de 1970 | B11: =COUNTIF('Livros por Ano'!$C$5:$C$439, A11) -> 58 | C11: =B11/$B$18 -> #DIV/0!
A12: Década de 1980 | B12: =COUNTIF('Livros por Ano'!$C$5:$C$439, A12) -> 102 | C12: =B12/$B$18 -> #DIV/0!
A13: Década de 1990 | B13: =COUNTIF('Livros por Ano'!$C$5:$C$439, A13) -> 58 | C13: =B13/$B$18 -> #DIV/0!
A14: Década de 2000 | B14: =COUNTIF('Livros por Ano'!$C$5:$C$439, A14) -> 11 | C14: =B14/$B$18 -> #DIV/0!
A15: Década de 2010 | B15: =COUNTIF('Livros por Ano'!$C$5:$C$439, A15) -> 1 | C15: =B15/$B$18 -> #DIV/0!
A16: Sem Data (S/D) | B16: =COUNTIF('Livros por Ano'!$C$5:$C$439, A16) -> 20 | C16: =B16/$B$18 -> #DIV/0!
A17: TOTAL GERAL | B17: =SUM(B5:B16) -> 433 | C17: =SUM(C5:C16) -> #DIV/0!
